<robot name="pupper_v3" version="1.0">
  <joint name="leg_back_l_1" type="revolute">
    <limit lower="-1.2200000" upper="2.5100000" effort="3.0000000" velocity="100.0000000"/>
    <origin rpy="3.1415927 0.0000000 0.0000000" xyz="-0.0750000 0.0725000 0.0000000"/>
    <parent link="base_link"/>
    <child link="leg_back_l_1"/>
    <axis xyz="0.0000000 0.0000000 1.0000000"/>
  </joint>
  <joint name="leg_back_l_2" type="revolute">
    <limit lower="-0.4200000" upper="3.1400001" effort="3.0000000" velocity="100.0000000"/>
    <origin rpy="1.4919850 -1.5707962 -1.4919850" xyz="0.0000000 0.0000000 0.0000000"/>
    <parent link="leg_back_l_1"/>
    <child link="leg_back_l_2"/>
    <axis xyz="0.0000000 0.0000000 1.0000000"/>
  </joint>
  <joint name="leg_back_l_3" type="revolute">
    <limit lower="-2.7900000" upper="0.6300000" effort="3.0000000" velocity="100.0000000"/>
    <origin rpy="-0.0000002 1.5707963 0.0000000" xyz="0.0000000 -0.0494000 0.0685000"/>
    <parent link="leg_back_l_2"/>
    <child link="leg_back_l_3"/>
    <axis xyz="0.0000000 0.0000000 1.0000000"/>
  </joint>
  <joint name="leg_back_r_1" type="revolute">
    <limit lower="-1.2200000" upper="2.5100000" effort="3.0000000" velocity="100.0000000"/>
    <origin rpy="1.5707963 0.0000000 0.0000000" xyz="-0.0750000 -0.0725000 0.0000000"/>
    <parent link="base_link"/>
    <child link="leg_back_r_1"/>
    <axis xyz="0.0000000 0.0000000 1.0000000"/>
  </joint>
  <joint name="leg_back_r_2" type="revolute">
    <limit lower="-0.4200000" upper="3.1400001" effort="3.0000000" velocity="100.0000000"/>
    <origin rpy="1.4919850 -1.5707962 -1.4919850" xyz="0.0000000 0.0000000 0.0000000"/>
    <parent link="leg_back_r_1"/>
    <child link="leg_back_r_2"/>
    <axis xyz="0.0000000 0.0000000 1.0000000"/>
  </joint>
  <joint name="leg_back_r_3" type="revolute">
    <limit lower="-2.7900000" upper="0.6300000" effort="3.0000000" velocity="100.0000000"/>
    <origin rpy="-0.0000002 1.5707963 0.0000000" xyz="0.0000000 -0.0494000 0.0685000"/>
    <parent link="leg_back_r_2"/>
    <child link="leg_back_r_3"/>
    <axis xyz="0.0000000 0.0000000 1.0000000"/>
  </joint>
  <joint name="leg_front_l_1" type="revolute">
    <limit lower="-1.2200000" upper="2.5100000" effort="3.0000000" velocity="100.0000000"/>
    <origin rpy="3.1415927 0.0000000 0.0000000" xyz="0.0750000 0.0835000 0.0000000"/>
    <parent link="base_link"/>
    <child link="leg_front_l_1"/>
    <axis xyz="0.0000000 0.0000000 1.0000000"/>
  </joint>
  <joint name="leg_front_l_2" type="revolute">
    <limit lower="-0.4200000" upper="3.1400001" effort="3.0000000" velocity="100.0000000"/>
    <origin rpy="1.4919850 -1.5707962 -1.4919850" xyz="0.0000000 0.0000000 0.0000000"/>
    <parent link="leg_front_l_1"/>
    <child link="leg_front_l_2"/>
    <axis xyz="0.0000000 0.0000000 1.0000000"/>
  </joint>
  <joint name="leg_front_l_3" type="revolute">
    <limit lower="-2.7900000" upper="0.6300000" effort="3.0000000" velocity="100.0000000"/>
    <origin rpy="-0.0000002 1.5707963 0.0000000" xyz="0.0000000 -0.0494000 0.0685000"/>
    <parent link="leg_front_l_2"/>
    <child link="leg_front_l_3"/>
    <axis xyz="0.0000000 0.0000000 1.0000000"/>
  </joint>
  <joint name="leg_front_r_1" type="revolute">
    <limit lower="-1.2200000" upper="2.5100000" effort="3.0000000" velocity="100.0000000"/>
    <origin rpy="1.5707963 0.0000000 0.0000000" xyz="0.0750000 -0.0835000 0.0000000"/>
    <parent link="base_link"/>
    <child link="leg_front_r_1"/>
    <axis xyz="0.0000000 0.0000000 1.0000000"/>
  </joint>
  <joint name="leg_front_r_2" type="revolute">
    <limit lower="-0.4200000" upper="3.1400001" effort="3.0000000" velocity="100.0000000"/>
    <origin rpy="1.4919850 -1.5707962 -1.4919850" xyz="0.0000000 0.0000000 0.0000000"/>
    <parent link="leg_front_r_1"/>
    <child link="leg_front_r_2"/>
    <axis xyz="0.0000000 0.0000000 1.0000000"/>
  </joint>
  <joint name="leg_front_r_3" type="revolute">
    <limit lower="-2.7900000" upper="0.6300000" effort="3.0000000" velocity="100.0000000"/>
    <origin rpy="-0.0000002 1.5707963 0.0000000" xyz="0.0000000 -0.0494000 0.0685000"/>
    <parent link="leg_front_r_2"/>
    <child link="leg_front_r_3"/>
    <axis xyz="0.0000000 0.0000000 1.0000000"/>
  </joint>
  <link name="base_link">
    <collision name="body_collision">
      <origin rpy="-1.5707964 -0.0000000 1.5707966" xyz="0.0214592 -0.0000000 0.0334458"/>
      <geometry>
        <box size="0.0901404 0.1275797 0.2594327"/>
      </geometry>
    </collision>
    <inertial>
      <inertia ixx="0.0021001" ixy="-0.0000009" ixz="-0.0004494" iyy="0.0059090" iyz="-0.0000018" izz="0.0050692"/>
      <origin rpy="0.0000000 0.0000000 0.0000000" xyz="0.0319513 -0.0000028 0.0244757"/>
      <mass value="1.0000000"/>
    </inertial>
    <visual name="body">
      <origin rpy="-1.5707963 -0.0000001 1.5707964" xyz="0.0000000 0.0000000 0.0000000"/>
      <geometry>
        <mesh filename="../meshes/dae/Body V4 v70.001.dae" scale="1.0000000 1.0000000 1.0000000"/>
      </geometry>
    </visual>
  </link>
  <link name="leg_back_l_1">
    <inertial>
      <inertia ixx="0.0000525" ixy="0.0000003" ixz="-0.0000006" iyy="0.0000329" iyz="-0.0000003" izz="0.0000432"/>
      <origin rpy="0.0000000 0.0000000 0.0000000" xyz="-0.0012942 0.0008054 -0.0059540"/>
      <mass value="0.1500000"/>
    </inertial>
    <visual name="Leg Assembly For Flanged v26.012">
      <origin rpy="0.0000000 0.0000002 3.1415927" xyz="0.0000000 0.0000000 -0.0280000"/>
      <geometry>
        <mesh filename="../meshes/dae/Leg Assembly For Flanged v26.013.dae" scale="-1.0000000 -1.0000000 -1.0000000"/>
      </geometry>
    </visual>
  </link>
  <link name="leg_back_l_2">
    <collision name="Cylinder.003">
      <origin rpy="-0.0000002 1.5707963 0.0000000" xyz="0.0000000 -0.0494000 0.0685000"/>
      <geometry>
        <cylinder radius="0.0250000" length="0.0300000"/>
      </geometry>
    </collision>
    <inertial>
      <inertia ixx="0.0000861" ixy="0.0000023" ixz="-0.0000574" iyy="0.0001472" iyz="0.0000025" izz="0.0000814"/>
      <origin rpy="0.0000000 0.0000000 0.0000000" xyz="-0.0017331 -0.0333999 0.0541872"/>
      <mass value="0.1500000"/>
    </inertial>
    <visual name="Leg Assembly For Flanged v26.013">
      <origin rpy="0.2621254 -1.5707962 2.8794674" xyz="-0.0280000 -0.0000000 -0.0000000"/>
      <geometry>
        <mesh filename="../meshes/dae/Leg Assembly For Flanged v26.014.dae" scale="-1.0000000 -1.0000000 -1.0000000"/>
      </geometry>
    </visual>
  </link>
  <link name="leg_back_l_3">
    <collision name="Leg Assembly For Flanged v26.016">
      <origin rpy="-0.0000002 0.0000002 3.1415927" xyz="0.0623077 -0.0621596 0.0180002"/>
      <geometry>
        <sphere radius="0.0199511"/>
      </geometry>
    </collision>
    <inertial>
      <inertia ixx="0.0000400" ixy="0.0000004" ixz="0.0000312" iyy="0.0000738" iyz="-0.0000002" izz="0.0000425"/>
      <origin rpy="0.0000000 0.0000000 0.0000000" xyz="0.0386593 -0.0358480 0.0183254"/>
      <mass value="0.0500000"/>
    </inertial>
    <visual name="Leg Assembly For Flanged v26.014">
      <origin rpy="-0.0000002 0.0000002 3.1415927" xyz="0.0685000 0.0494000 -0.0280000"/>
      <geometry>
        <mesh filename="../meshes/dae/Leg Assembly For Flanged v26.015.dae" scale="-1.0000000 -1.0000000 -1.0000000"/>
      </geometry>
    </visual>
  </link>
  <link name="leg_back_r_1">
    <inertial>
      <inertia ixx="0.0000525" ixy="0.0000003" ixz="-0.0000006" iyy="0.0000329" iyz="-0.0000003" izz="0.0000432"/>
      <origin rpy="0.0000000 0.0000000 0.0000000" xyz="-0.0012942 0.0008054 -0.0059540"/>
      <mass value="0.1500000"/>
    </inertial>
    <visual name="Leg Assembly For Flanged v26.004">
      <origin rpy="0.0000000 0.0000002 3.1415927" xyz="0.0000000 0.0000000 -0.0280000"/>
      <geometry>
        <mesh filename="../meshes/dae/Leg Assembly For Flanged v26.005.dae" scale="1.0000000 1.0000000 1.0000000"/>
      </geometry>
    </visual>
  </link>
  <link name="leg_back_r_2">
    <collision name="Cylinder.001">
      <origin rpy="-0.0000002 1.5707963 0.0000000" xyz="0.0000000 -0.0494000 0.0685000"/>
      <geometry>
        <cylinder radius="0.0250000" length="0.0300000"/>
      </geometry>
    </collision>
    <inertial>
      <inertia ixx="0.0000861" ixy="0.0000023" ixz="-0.0000574" iyy="0.0001472" iyz="0.0000025" izz="0.0000814"/>
      <origin rpy="0.0000000 0.0000000 0.0000000" xyz="-0.0017331 -0.0333999 0.0541872"/>
      <mass value="0.1500000"/>
    </inertial>
    <visual name="Leg Assembly For Flanged v26.005">
      <origin rpy="0.2621254 -1.5707962 2.8794674" xyz="-0.0280000 -0.0000000 -0.0000000"/>
      <geometry>
        <mesh filename="../meshes/dae/Leg Assembly For Flanged v26.006.dae" scale="1.0000000 1.0000000 1.0000000"/>
      </geometry>
    </visual>
  </link>
  <link name="leg_back_r_3">
    <collision name="Leg Assembly For Flanged v26.008">
      <origin rpy="-0.0000002 0.0000002 3.1415927" xyz="0.0623077 -0.0621596 0.0180002"/>
      <geometry>
        <sphere radius="0.0199511"/>
      </geometry>
    </collision>
    <inertial>
      <inertia ixx="0.0000400" ixy="0.0000004" ixz="0.0000312" iyy="0.0000738" iyz="-0.0000002" izz="0.0000425"/>
      <origin rpy="0.0000000 0.0000000 0.0000000" xyz="0.0386593 -0.0358480 0.0183254"/>
      <mass value="0.0500000"/>
    </inertial>
    <visual name="Leg Assembly For Flanged v26.006">
      <origin rpy="-0.0000002 0.0000002 3.1415927" xyz="0.0685000 0.0494000 -0.0280000"/>
      <geometry>
        <mesh filename="../meshes/dae/Leg Assembly For Flanged v26.007.dae" scale="1.0000000 1.0000000 1.0000000"/>
      </geometry>
    </visual>
  </link>
  <link name="leg_front_l_1">
    <inertial>
      <inertia ixx="0.0000525" ixy="0.0000003" ixz="-0.0000006" iyy="0.0000329" iyz="-0.0000003" izz="0.0000432"/>
      <origin rpy="0.0000000 0.0000000 0.0000000" xyz="-0.0012942 0.0008054 -0.0059540"/>
      <mass value="0.1500000"/>
    </inertial>
    <visual name="Leg Assembly For Flanged v26.009">
      <origin rpy="0.0000000 0.0000002 3.1415927" xyz="0.0000000 0.0000000 -0.0280000"/>
      <geometry>
        <mesh filename="../meshes/dae/Leg Assembly For Flanged v26.010.dae" scale="-1.0000000 -1.0000000 -1.0000000"/>
      </geometry>
    </visual>
  </link>
  <link name="leg_front_l_2">
    <collision name="Cylinder.002">
      <origin rpy="-0.0000002 1.5707963 0.0000000" xyz="0.0000000 -0.0494000 0.0685000"/>
      <geometry>
        <cylinder radius="0.0250000" length="0.0300000"/>
      </geometry>
    </collision>
    <inertial>
      <inertia ixx="0.0000861" ixy="0.0000023" ixz="-0.0000574" iyy="0.0001472" iyz="0.0000025" izz="0.0000814"/>
      <origin rpy="0.0000000 0.0000000 0.0000000" xyz="-0.0017331 -0.0334000 0.0541872"/>
      <mass value="0.1500000"/>
    </inertial>
    <visual name="Leg Assembly For Flanged v26.010">
      <origin rpy="0.2621254 -1.5707962 2.8794674" xyz="-0.0280000 -0.0000000 -0.0000000"/>
      <geometry>
        <mesh filename="../meshes/dae/Leg Assembly For Flanged v26.011.dae" scale="-1.0000000 -1.0000000 -1.0000000"/>
      </geometry>
    </visual>
  </link>
  <link name="leg_front_l_3">
    <collision name="Leg Assembly For Flanged v26.015">
      <origin rpy="-0.0000002 0.0000002 3.1415927" xyz="0.0623078 -0.0621596 0.0180002"/>
      <geometry>
        <sphere radius="0.0199511"/>
      </geometry>
    </collision>
    <inertial>
      <inertia ixx="0.0000400" ixy="0.0000004" ixz="0.0000312" iyy="0.0000738" iyz="-0.0000002" izz="0.0000425"/>
      <origin rpy="0.0000000 0.0000000 0.0000000" xyz="0.0386593 -0.0358480 0.0183254"/>
      <mass value="0.0500000"/>
    </inertial>
    <visual name="Leg Assembly For Flanged v26.011">
      <origin rpy="-0.0000002 0.0000002 3.1415927" xyz="0.0685000 0.0494000 -0.0280000"/>
      <geometry>
        <mesh filename="../meshes/dae/Leg Assembly For Flanged v26.012.dae" scale="-1.0000000 -1.0000000 -1.0000000"/>
      </geometry>
    </visual>
  </link>
  <link name="leg_front_r_1">
    <inertial>
      <inertia ixx="0.0000525" ixy="0.0000003" ixz="-0.0000006" iyy="0.0000329" iyz="-0.0000003" izz="0.0000432"/>
      <origin rpy="0.0000000 0.0000000 0.0000000" xyz="-0.0012942 0.0008054 -0.0059540"/>
      <mass value="0.1500000"/>
    </inertial>
    <visual name="Leg Assembly For Flanged v26.001">
      <origin rpy="0.0000000 0.0000002 3.1415927" xyz="0.0000000 0.0000000 -0.0280000"/>
      <geometry>
        <mesh filename="../meshes/dae/Leg Assembly For Flanged v26.001.dae" scale="1.0000000 1.0000000 1.0000000"/>
      </geometry>
    </visual>
  </link>
  <link name="leg_front_r_2">
    <collision name="Cylinder">
      <origin rpy="-0.0000002 1.5707963 0.0000000" xyz="0.0000000 -0.0494000 0.0685000"/>
      <geometry>
        <cylinder radius="0.0250000" length="0.0300000"/>
      </geometry>
    </collision>
    <inertial>
      <inertia ixx="0.0000861" ixy="0.0000023" ixz="-0.0000574" iyy="0.0001472" iyz="0.0000025" izz="0.0000814"/>
      <origin rpy="0.0000000 0.0000000 0.0000000" xyz="-0.0017331 -0.0334000 0.0541872"/>
      <mass value="0.1500000"/>
    </inertial>
    <visual name="Leg Assembly For Flanged v26.002">
      <origin rpy="0.2621254 -1.5707962 2.8794674" xyz="-0.0280000 -0.0000000 -0.0000000"/>
      <geometry>
        <mesh filename="../meshes/dae/Leg Assembly For Flanged v26.002.dae" scale="1.0000000 1.0000000 1.0000000"/>
      </geometry>
    </visual>
  </link>
  <link name="leg_front_r_3">
    <collision name="Leg Assembly For Flanged v26.007">
      <origin rpy="-0.0000002 0.0000002 3.1415927" xyz="0.0623078 -0.0621596 0.0180002"/>
      <geometry>
        <sphere radius="0.0199511"/>
      </geometry>
    </collision>
    <inertial>
      <inertia ixx="0.0000400" ixy="0.0000004" ixz="0.0000312" iyy="0.0000738" iyz="-0.0000002" izz="0.0000425"/>
      <origin rpy="0.0000000 0.0000000 0.0000000" xyz="0.0386593 -0.0358480 0.0183254"/>
      <mass value="0.0500000"/>
    </inertial>
    <visual name="Leg Assembly For Flanged v26.003">
      <origin rpy="-0.0000002 0.0000002 3.1415927" xyz="0.0685000 0.0494000 -0.0280000"/>
      <geometry>
        <mesh filename="../meshes/dae/Leg Assembly For Flanged v26.003.dae" scale="1.0000000 1.0000000 1.0000000"/>
      </geometry>
    </visual>
  </link>
</robot>