<robot name="pupper_v3" version="1.0">
  <joint name="leg_back_l_1" type="revolute">
    <limit lower="-1.22000" upper="2.51000" effort="3.00000" velocity="100.00000"/>
    <origin rpy="3.14159 0.00000 0.00000" xyz="-0.07500 0.07250 0.00000"/>
    <parent link="base_link"/>
    <child link="leg_back_l_1"/>
    <axis xyz="0.00000 0.00000 1.00000"/>
  </joint>
  <joint name="leg_back_l_2" type="revolute">
    <limit lower="-0.42000" upper="3.14000" effort="3.00000" velocity="100.00000"/>
    <origin rpy="1.49199 -1.57080 -1.49198" xyz="0.00000 0.00000 0.00000"/>
    <parent link="leg_back_l_1"/>
    <child link="leg_back_l_2"/>
    <axis xyz="0.00000 0.00000 1.00000"/>
  </joint>
  <joint name="leg_back_l_3" type="revolute">
    <limit lower="-2.79000" upper="0.63000" effort="3.00000" velocity="100.00000"/>
    <origin rpy="-0.00000 1.57080 0.00000" xyz="0.00000 -0.04940 0.06850"/>
    <parent link="leg_back_l_2"/>
    <child link="leg_back_l_3"/>
    <axis xyz="0.00000 0.00000 1.00000"/>
  </joint>
  <joint name="leg_back_r_1" type="revolute">
    <limit lower="-1.22000" upper="2.51000" effort="3.00000" velocity="100.00000"/>
    <origin rpy="1.57080 0.00000 0.00000" xyz="-0.07500 -0.07250 0.00000"/>
    <parent link="base_link"/>
    <child link="leg_back_r_1"/>
    <axis xyz="0.00000 0.00000 1.00000"/>
  </joint>
  <joint name="leg_back_r_2" type="revolute">
    <limit lower="-0.42000" upper="3.14000" effort="3.00000" velocity="100.00000"/>
    <origin rpy="1.49199 -1.57080 -1.49198" xyz="0.00000 0.00000 0.00000"/>
    <parent link="leg_back_r_1"/>
    <child link="leg_back_r_2"/>
    <axis xyz="0.00000 0.00000 1.00000"/>
  </joint>
  <joint name="leg_back_r_3" type="revolute">
    <limit lower="-2.79000" upper="0.63000" effort="3.00000" velocity="100.00000"/>
    <origin rpy="-0.00000 1.57080 0.00000" xyz="0.00000 -0.04940 0.06850"/>
    <parent link="leg_back_r_2"/>
    <child link="leg_back_r_3"/>
    <axis xyz="0.00000 0.00000 1.00000"/>
  </joint>
  <joint name="leg_front_l_1" type="revolute">
    <limit lower="-1.22000" upper="2.51000" effort="3.00000" velocity="100.00000"/>
    <origin rpy="3.14159 0.00000 0.00000" xyz="0.07500 0.08350 0.00000"/>
    <parent link="base_link"/>
    <child link="leg_front_l_1"/>
    <axis xyz="0.00000 0.00000 1.00000"/>
  </joint>
  <joint name="leg_front_l_2" type="revolute">
    <limit lower="-0.42000" upper="3.14000" effort="3.00000" velocity="100.00000"/>
    <origin rpy="1.49199 -1.57080 -1.49198" xyz="0.00000 0.00000 0.00000"/>
    <parent link="leg_front_l_1"/>
    <child link="leg_front_l_2"/>
    <axis xyz="0.00000 0.00000 1.00000"/>
  </joint>
  <joint name="leg_front_l_3" type="revolute">
    <limit lower="-2.79000" upper="0.63000" effort="3.00000" velocity="100.00000"/>
    <origin rpy="-0.00000 1.57080 0.00000" xyz="0.00000 -0.04940 0.06850"/>
    <parent link="leg_front_l_2"/>
    <child link="leg_front_l_3"/>
    <axis xyz="0.00000 0.00000 1.00000"/>
  </joint>
  <joint name="leg_front_r_1" type="revolute">
    <limit lower="-1.22000" upper="2.51000" effort="3.00000" velocity="100.00000"/>
    <origin rpy="1.57080 0.00000 0.00000" xyz="0.07500 -0.08350 0.00000"/>
    <parent link="base_link"/>
    <child link="leg_front_r_1"/>
    <axis xyz="0.00000 0.00000 1.00000"/>
  </joint>
  <joint name="leg_front_r_2" type="revolute">
    <limit lower="-0.42000" upper="3.14000" effort="3.00000" velocity="100.00000"/>
    <origin rpy="1.49199 -1.57080 -1.49198" xyz="0.00000 0.00000 0.00000"/>
    <parent link="leg_front_r_1"/>
    <child link="leg_front_r_2"/>
    <axis xyz="0.00000 0.00000 1.00000"/>
  </joint>
  <joint name="leg_front_r_3" type="revolute">
    <limit lower="-2.79000" upper="0.63000" effort="3.00000" velocity="100.00000"/>
    <origin rpy="-0.00000 1.57080 0.00000" xyz="0.00000 -0.04940 0.06850"/>
    <parent link="leg_front_r_2"/>
    <child link="leg_front_r_3"/>
    <axis xyz="0.00000 0.00000 1.00000"/>
  </joint>
  <link name="base_link">
    <collision name="body_collision">
      <origin rpy="-1.57080 -0.00000 1.57080" xyz="0.02146 -0.00000 0.03345"/>
      <geometry>
        <box size="0.09014 0.12758 0.25943"/>
      </geometry>
    </collision>
    <inertial>
      <inertia ixx="0.00240" ixy="0.00010" ixz="0.00010" iyy="0.00850" iyz="0.00010" izz="0.00850"/>
      <origin rpy="0.00000 0.00000 0.00000" xyz="0.02500 0.00000 0.01500"/>
      <mass value="1.50000"/>
    </inertial>
    <visual name="body">
      <origin rpy="-1.57080 -0.00000 1.57080" xyz="0.00000 0.00000 0.00000"/>
      <geometry>
        <mesh filename="../meshes/stl/Body V4 v70.001.stl" scale="1.00000 1.00000 1.00000"/>
      </geometry>
    </visual>
  </link>
  <link name="leg_back_l_1">
    <inertial>
      <inertia ixx="0.00005" ixy="0.00000" ixz="-0.00000" iyy="0.00003" iyz="-0.00000" izz="0.00004"/>
      <origin rpy="0.00000 0.00000 0.00000" xyz="-0.00129 0.00081 -0.00595"/>
      <mass value="0.15000"/>
    </inertial>
    <visual name="Leg Assembly For Flanged v26.012">
      <origin rpy="0.00000 0.00000 3.14159" xyz="0.00000 0.00000 -0.02800"/>
      <geometry>
        <mesh filename="../meshes/stl/Leg Assembly For Flanged v26.013.stl" scale="-1.00000 -1.00000 -1.00000"/>
      </geometry>
    </visual>
  </link>
  <link name="leg_back_l_2">
    <collision name="Cylinder.003">
      <origin rpy="-0.00000 1.57080 0.00000" xyz="0.00000 -0.04940 0.06850"/>
      <geometry>
        <cylinder radius="0.02500" length="0.03000"/>
      </geometry>
    </collision>
    <inertial>
      <inertia ixx="0.00009" ixy="0.00000" ixz="-0.00006" iyy="0.00015" iyz="0.00000" izz="0.00008"/>
      <origin rpy="0.00000 0.00000 0.00000" xyz="-0.00173 -0.03340 0.05419"/>
      <mass value="0.15000"/>
    </inertial>
    <visual name="Leg Assembly For Flanged v26.013">
      <origin rpy="0.26213 -1.57080 2.87947" xyz="-0.02800 -0.00000 -0.00000"/>
      <geometry>
        <mesh filename="../meshes/stl/Leg Assembly For Flanged v26.014.stl" scale="-1.00000 -1.00000 -1.00000"/>
      </geometry>
    </visual>
  </link>
  <link name="leg_back_l_3">
    <collision name="Leg Assembly For Flanged v26.016">
      <origin rpy="-0.00000 0.00000 3.14159" xyz="0.06231 -0.06216 0.01800"/>
      <geometry>
        <sphere radius="0.01995"/>
      </geometry>
    </collision>
    <inertial>
      <inertia ixx="0.00004" ixy="0.00000" ixz="0.00003" iyy="0.00007" iyz="-0.00000" izz="0.00004"/>
      <origin rpy="0.00000 0.00000 0.00000" xyz="0.03866 -0.03585 0.01833"/>
      <mass value="0.05000"/>
    </inertial>
    <visual name="Leg Assembly For Flanged v26.014">
      <origin rpy="-0.00000 0.00000 3.14159" xyz="0.06850 0.04940 -0.02800"/>
      <geometry>
        <mesh filename="../meshes/stl/Leg Assembly For Flanged v26.015.stl" scale="-1.00000 -1.00000 -1.00000"/>
      </geometry>
    </visual>
  </link>
  <link name="leg_back_r_1">
    <inertial>
      <inertia ixx="0.00005" ixy="0.00000" ixz="-0.00000" iyy="0.00003" iyz="-0.00000" izz="0.00004"/>
      <origin rpy="0.00000 0.00000 0.00000" xyz="-0.00129 0.00081 -0.00595"/>
      <mass value="0.15000"/>
    </inertial>
    <visual name="Leg Assembly For Flanged v26.004">
      <origin rpy="0.00000 0.00000 3.14159" xyz="0.00000 0.00000 -0.02800"/>
      <geometry>
        <mesh filename="../meshes/stl/Leg Assembly For Flanged v26.005.stl" scale="1.00000 1.00000 1.00000"/>
      </geometry>
    </visual>
  </link>
  <link name="leg_back_r_2">
    <collision name="Cylinder.001">
      <origin rpy="-0.00000 1.57080 0.00000" xyz="0.00000 -0.04940 0.06850"/>
      <geometry>
        <cylinder radius="0.02500" length="0.03000"/>
      </geometry>
    </collision>
    <inertial>
      <inertia ixx="0.00009" ixy="0.00000" ixz="-0.00006" iyy="0.00015" iyz="0.00000" izz="0.00008"/>
      <origin rpy="0.00000 0.00000 0.00000" xyz="-0.00173 -0.03340 0.05419"/>
      <mass value="0.15000"/>
    </inertial>
    <visual name="Leg Assembly For Flanged v26.005">
      <origin rpy="0.26213 -1.57080 2.87947" xyz="-0.02800 -0.00000 -0.00000"/>
      <geometry>
        <mesh filename="../meshes/stl/Leg Assembly For Flanged v26.006.stl" scale="1.00000 1.00000 1.00000"/>
      </geometry>
    </visual>
  </link>
  <link name="leg_back_r_3">
    <collision name="Leg Assembly For Flanged v26.008">
      <origin rpy="-0.00000 0.00000 3.14159" xyz="0.06231 -0.06216 0.01800"/>
      <geometry>
        <sphere radius="0.01995"/>
      </geometry>
    </collision>
    <inertial>
      <inertia ixx="0.00004" ixy="0.00000" ixz="0.00003" iyy="0.00007" iyz="-0.00000" izz="0.00004"/>
      <origin rpy="0.00000 0.00000 0.00000" xyz="0.03866 -0.03585 0.01833"/>
      <mass value="0.05000"/>
    </inertial>
    <visual name="Leg Assembly For Flanged v26.006">
      <origin rpy="-0.00000 0.00000 3.14159" xyz="0.06850 0.04940 -0.02800"/>
      <geometry>
        <mesh filename="../meshes/stl/Leg Assembly For Flanged v26.007.stl" scale="1.00000 1.00000 1.00000"/>
      </geometry>
    </visual>
  </link>
  <link name="leg_front_l_1">
    <inertial>
      <inertia ixx="0.00005" ixy="0.00000" ixz="-0.00000" iyy="0.00003" iyz="-0.00000" izz="0.00004"/>
      <origin rpy="0.00000 0.00000 0.00000" xyz="-0.00129 0.00081 -0.00595"/>
      <mass value="0.15000"/>
    </inertial>
    <visual name="Leg Assembly For Flanged v26.009">
      <origin rpy="0.00000 0.00000 3.14159" xyz="0.00000 0.00000 -0.02800"/>
      <geometry>
        <mesh filename="../meshes/stl/Leg Assembly For Flanged v26.010.stl" scale="-1.00000 -1.00000 -1.00000"/>
      </geometry>
    </visual>
  </link>
  <link name="leg_front_l_2">
    <collision name="Cylinder.002">
      <origin rpy="-0.00000 1.57080 0.00000" xyz="0.00000 -0.04940 0.06850"/>
      <geometry>
        <cylinder radius="0.02500" length="0.03000"/>
      </geometry>
    </collision>
    <inertial>
      <inertia ixx="0.00009" ixy="0.00000" ixz="-0.00006" iyy="0.00015" iyz="0.00000" izz="0.00008"/>
      <origin rpy="0.00000 0.00000 0.00000" xyz="-0.00173 -0.03340 0.05419"/>
      <mass value="0.15000"/>
    </inertial>
    <visual name="Leg Assembly For Flanged v26.010">
      <origin rpy="0.26213 -1.57080 2.87947" xyz="-0.02800 -0.00000 -0.00000"/>
      <geometry>
        <mesh filename="../meshes/stl/Leg Assembly For Flanged v26.011.stl" scale="-1.00000 -1.00000 -1.00000"/>
      </geometry>
    </visual>
  </link>
  <link name="leg_front_l_3">
    <collision name="Leg Assembly For Flanged v26.015">
      <origin rpy="-0.00000 0.00000 3.14159" xyz="0.06231 -0.06216 0.01800"/>
      <geometry>
        <sphere radius="0.01995"/>
      </geometry>
    </collision>
    <inertial>
      <inertia ixx="0.00004" ixy="0.00000" ixz="0.00003" iyy="0.00007" iyz="-0.00000" izz="0.00004"/>
      <origin rpy="0.00000 0.00000 0.00000" xyz="0.03866 -0.03585 0.01833"/>
      <mass value="0.05000"/>
    </inertial>
    <visual name="Leg Assembly For Flanged v26.011">
      <origin rpy="-0.00000 0.00000 3.14159" xyz="0.06850 0.04940 -0.02800"/>
      <geometry>
        <mesh filename="../meshes/stl/Leg Assembly For Flanged v26.012.stl" scale="-1.00000 -1.00000 -1.00000"/>
      </geometry>
    </visual>
  </link>
  <link name="leg_front_r_1">
    <inertial>
      <inertia ixx="0.00005" ixy="0.00000" ixz="-0.00000" iyy="0.00003" iyz="-0.00000" izz="0.00004"/>
      <origin rpy="0.00000 0.00000 0.00000" xyz="-0.00129 0.00081 -0.00595"/>
      <mass value="0.15000"/>
    </inertial>
    <visual name="Leg Assembly For Flanged v26.001">
      <origin rpy="0.00000 0.00000 3.14159" xyz="0.00000 0.00000 -0.02800"/>
      <geometry>
        <mesh filename="../meshes/stl/Leg Assembly For Flanged v26.001.stl" scale="1.00000 1.00000 1.00000"/>
      </geometry>
    </visual>
  </link>
  <link name="leg_front_r_2">
    <collision name="Cylinder">
      <origin rpy="-0.00000 1.57080 0.00000" xyz="0.00000 -0.04940 0.06850"/>
      <geometry>
        <cylinder radius="0.02500" length="0.03000"/>
      </geometry>
    </collision>
    <inertial>
      <inertia ixx="0.00009" ixy="0.00000" ixz="-0.00006" iyy="0.00015" iyz="0.00000" izz="0.00008"/>
      <origin rpy="0.00000 0.00000 0.00000" xyz="-0.00173 -0.03340 0.05419"/>
      <mass value="0.15000"/>
    </inertial>
    <visual name="Leg Assembly For Flanged v26.002">
      <origin rpy="0.26213 -1.57080 2.87947" xyz="-0.02800 -0.00000 -0.00000"/>
      <geometry>
        <mesh filename="../meshes/stl/Leg Assembly For Flanged v26.002.stl" scale="1.00000 1.00000 1.00000"/>
      </geometry>
    </visual>
  </link>
  <link name="leg_front_r_3">
    <collision name="Leg Assembly For Flanged v26.007">
      <origin rpy="-0.00000 0.00000 3.14159" xyz="0.06231 -0.06216 0.01800"/>
      <geometry>
        <sphere radius="0.01995"/>
      </geometry>
    </collision>
    <inertial>
      <inertia ixx="0.00004" ixy="0.00000" ixz="0.00003" iyy="0.00007" iyz="-0.00000" izz="0.00004"/>
      <origin rpy="0.00000 0.00000 0.00000" xyz="0.03866 -0.03585 0.01833"/>
      <mass value="0.05000"/>
    </inertial>
    <visual name="Leg Assembly For Flanged v26.003">
      <origin rpy="-0.00000 0.00000 3.14159" xyz="0.06850 0.04940 -0.02800"/>
      <geometry>
        <mesh filename="../meshes/stl/Leg Assembly For Flanged v26.003.stl" scale="1.00000 1.00000 1.00000"/>
      </geometry>
    </visual>
  </link>
</robot>